Workbook

Sheet SA Summary
A1: Standardized Approach - Capital Charge Summary
D3: SBM | I3: Sum
D4: GIRR | E4: CSR | F4: FX | G4: EQ | H4: COMM
B5: Medium (Base) Correlation | C5: Delta | D5: =GIRR!D85 -> 2943.7576 | E5: 0 | F5: 0 | G5: =SBM!E67 -> 27.87 | H5: 0 | I5: =SUM(D5:H7) -> 2982.9876
C6: Vega | D6: 0 | E6: 0 | F6: 0 | G6: =SBM!E143 -> 4.3 | H6: 0
C7: Curvature | D7: 0 | E7: 0 | F7: 0 | G7: =SBM!E194 -> 7.06 | H7: 0
B8: High Correlation | C8: Delta | D8: =GIRR!D86 -> 3172.9466 | E8: 0 | F8: 0 | G8: =SBM!E68 -> 28.05 | H8: 0 | I8: =SUM(D8:H10) -> 3212.1766
C9: Vega | D9: 0 | E9: 0 | F9: 0 | G9: =SBM!E144 -> 4.16 | H9: 0
C10: Curvature | D10: 0 | E10: 0 | F10: 0 | G10: =SBM!E195 -> 7.02 | H10: 0
B11: Low Correlation | C11: Delta | D11: =GIRR!D87 -> 2628.5949 | E11: 0 | F11: 0 | G11: =SBM!E69 -> 27.7 | H11: 0 | I11: =SUM(D11:H13) -> 2667.6949
C12: Vega | D12: 0 | E12: 0 | F12: 0 | G12: =SBM!E145 -> 4.29 | H12: 0
C13: Curvature | D13: 0 | E13: 0 | F13: 0 | G13: =SBM!E196 -> 7.11 | H13: 0
B16: SBM Charge | C16: =MAX(I5:I13) -> 3212.1766
B17: DRC Charge | C17: =DRC!B79 -> 158.13632
B18: RRAO Charge | C18: =RRAO!B19 -> 6336
B21: Total SA Charge | C21: =SUM(C16:C18) -> 9706.3129

Sheet DRC
A1: DRC based capital charge (example for non-securitization positions)
A3: Instrument Class | B3: LGD | D3: Field | E3: Used For
A4: Senior debt | B4: 0.75 | D4: Instrument Class | E4: LGD Value
A5: Covered bonds | B5: 0.25 | D5: Category | E5: Bucket Selection
A6: Other | B6: 1 | D6: Rating | E6: Risk Weight (or PD) Value
D7: Notional, Market Value, LGD | E7: JTD Calculation
A9: Obligor | B9: Instrument | C9: Category | D9: Rating | E9: Notional | F9: LGD | G9: Market value
A10: A.001 | B10: Covered Bond | C10: Corporate | D10: AA | E10: 1000 | F10: 0.25 | G10: 800
A11: A.002 | B11: Municipality | C11: Municipality | D11: AAA | E11: -1000 | F11: 0.75 | G11: -950
A12: A.003 | B12: Sovereign | C12: Sovereign | D12: AAA | E12: 1000 | F12: 0.75 | G12: 970
A13: A.004 | B13: Corporate Bond | C13: Corporate | D13: NR | E13: -1000 | F13: 0.75 | G13: 450
A14: A.001 | B14: Stock 1 | C14: Corporate | D14: BBB | F14: 1 | G14: 760
A15: A.001 | B15: Long call on stock 1 | C15: Corporate | D15: BBB | F15: 1 | G15: 15.605309
A17: Gross JTD - Instrument Level
A20: Obligor | B20: JTD + | C20: JTD -
A21: A.001 | B21: =MAX(F10*E10+(G10-E10),0) -> 50 | C21: =MIN(F10*E10+(G10-E10),0) -> 0
A22: A.002 | B22: =MAX(F11*E11+(G11-E11),0) -> 0 | C22: =MIN(F11*E11+(G11-E11),0) -> -700
A23: A.003 | B23: =MAX(F12*E12+(G12-E12),0) -> 720 | C23: =MIN(F12*E12+(G12-E12),0) -> 0
A24: A.004 | B24: =MAX(F13*E13+(G13-E13),0) -> 700 | C24: =MIN(F13*E13+(G13-E13),0) -> 0
A25: A.001 | B25: =MAX(F14*E14+(G14-E14),0) -> 760 | C25: =MIN(F14*E14+(G14-E14),0) -> 0
A26: A.001 | B26: =MAX(F15*E15+(G15-E15),0) -> 15.605309 | C26: =MIN(F15*E15+(G15-E15),0) -> 0
A28: Gross JTD - Obligor Level
A31: Obligor | B31: JTD + | C31: JTD -
A32: A.001 | B32: =B21+B25+B26 -> 825.60531 | C32: =C21+C25+C26 -> 0
A33: A.002 | B33: =B22 -> 0 | C33: =C22 -> -700
A34: A.003 | B34: =B23 -> 720 | C34: =C23 -> 0
A35: A.004 | B35: =B24 -> 700 | C35: =C24 -> 0
A37: Net JTD - Obligor Level
A39: Obligor | B39: Net JTD
A40: A.001 | B40: =B32+C32 -> 825.60531
A41: A.002 | B41: =B33+C33 -> -700
A42: A.003 | B42: =B34+C34 -> 720
A43: A.004 | B43: =B35+C35 -> 700
A45: Risk weight assignment
A47: Rating band | B47: Risk weight
A48: AAA | B48: 0.005
A49: AA | B49: 0.02
A50: A | B50: 0.03
A51: BBB | B51: 0.06
A52: BB | B52: 0.15
...

Sheet RRAO
A1: RRAO based capital charge
A3: Risk Weights
A4: Exotic Underlying | B4: 0.01
A5: Other Residual Risk | B5: 0.001
A7: Instrument | B7: RRAO Classification | C7: Notional | D7: Risk Weight | E7: Charge
A8: I.001 | B8: Exotic Underlying | C8: 30000 | D8: =VLOOKUP(B8,$A$4:$B$5,2,0) -> 0.01 | E8: =C8*D8 -> 300
A9: I.002 | B9: Other Residual Risk | C9: 10000 | D9: =VLOOKUP(B9,$A$4:$B$5,2,0) -> 0.001 | E9: =C9*D9 -> 10
A10: I.003 | B10: Exotic Underlying | C10: 9000 | D10: =VLOOKUP(B10,$A$4:$B$5,2,0) -> 0.01 | E10: =C10*D10 -> 90
A11: I.004 | B11: Other Residual Risk | C11: 300000 | D11: =VLOOKUP(B11,$A$4:$B$5,2,0) -> 0.001 | E11: =C11*D11 -> 300
A12: I.005 | B12: Exotic Underlying | C12: 500000 | D12: =VLOOKUP(B12,$A$4:$B$5,2,0) -> 0.01 | E12: =C12*D12 -> 5000
A13: I.006 | B13: Other Residual Risk | C13: 30000 | D13: =VLOOKUP(B13,$A$4:$B$5,2,0) -> 0.001 | E13: =C13*D13 -> 30
A14: I.007 | B14: Other Residual Risk | C14: 500000 | D14: =VLOOKUP(B14,$A$4:$B$5,2,0) -> 0.001 | E14: =C14*D14 -> 500
A15: I.008 | B15: Other Residual Risk | C15: 6000 | D15: =VLOOKUP(B15,$A$4:$B$5,2,0) -> 0.001 | E15: =C15*D15 -> 6
A16: I.009 | B16: Exotic Underlying | C16: 10000 | D16: =VLOOKUP(B16,$A$4:$B$5,2,0) -> 0.01 | E16: =C16*D16 -> 100
A19: Total Charge | B19: =SUM(E8:E16) -> 6336
D23: PD * LGD * EAD | E23: = | F23: RW * JTD

Sheet SBM
A1: 1) Equity Delta
A2: Bucket # | B2: Market Cap | C2: Economy | D2: Sector | F2: Bucket # | G2: Risk Weight for Equity Spot Price | H2: Risk Weight for Equity Repo Rate
A3: 1 | B3: Large | C3: Emerging | D3: Consumer, Utilities, HealthCare | F3: 1 | G3: 0.55 | H3: 0.0055
A4: 2 | D4: Telecommunications, Industrials | F4: 2 | G4: 0.6 | H4: 0.006
A5: 3 | D5: Basic materials, Energy | F5: 3 | G5: 0.45 | H5: 0.0045 | K5: e = 2.7183
A6: 4 | D6: Financial, Technology | F6: 4 | G6: 0.55 | H6: 0.0055
A7: 5 | C7: Advanced | D7: Consumer, Utilities, HealthCare | F7: 5 | G7: 0.3 | H7: 0.003
A8: 6 | D8: Telecommunications, Industrials | F8: 6 | G8: 0.35 | H8: 0.0035
A9: 7 | D9: Basic materials, Energy | F9: 7 | G9: 0.4 | H9: 0.004
A10: 8 | D10: Financial, Technology | F10: 8 | G10: 0.5 | H10: 0.005
A11: 9 | B11: Small | C11: Emerging | D11: All sectors | F11: 9 | G11: 0.7 | H11: 0.007
A12: 10 | C12: Advanced | D12: All sectors | F12: 10 | G12: 0.5 | H12: 0.005
A13: 11 | F13: Residual Bucket | G13: 0.7 | H13: 0.007
A16: Instrument | B16: Long / Short | C16: Bucket Number | D16: Underlying Price | E16: Strike | F16: Implied Vol | G16: Option Maturity | H16: Interest Rate | I16: d1 | J16: d2 | K16: N(d1) = Delta | L16: N (d2) | M16: Option Price | N16: Vega | O16: Delta Cash
A17: Equity A | B17: Long | C17: 6 | D17: 40 | E17: N/A | F17: N/A | G17: N/A | H17: N/A | I17: N/A | J17: N/A | K17: 1 | L17: N/A | M17: N/A | N17: N/A | O17: =D17 * K17 -> 40
A18: European Call on A | B18: Long | C18: 6 | D18: 40 | E18: 40 | F18: 0.25 | G18: 1 | H18: 0.014 | I18: 0.181 | J18: =I18-F18*(1)^0.5 -> -0.069 | K18: =NORMSDIST(I18) -> 0.57181621 | L18: =NORMSDIST(J18) -> 0.47249481 | M18: 4.24 | N18: =IF(B18="Long", 1, -1) * D18 * SQRT(G18) * NORMDIST(I18, 0, 1, FALSE) -> 15.698426 | O18: =D18 * K18 -> 22.872648
A19: European Call on B | B19: Short | C19: 6 | D19: 25 | E19: 30 | F19: 0.3 | G19: 2 | H19: 0.022 | I19: -0.11 | J19: =I19-F19*(2)^0.5 -> -0.53426407 | K19: =-NORMSDIST(I19) -> -0.45620469 | L19: =NORMSDIST(J19) -> 0.29657942 | M19: 2.89 | N19: =IF(B19="Long", 1, -1) * D19 * SQRT(G19) * NORMDIST(I19, 0, 1, FALSE) -> -14.019664 | O19: =D19 * K19 -> -11.405117
A20: European Call on C | B20: Long | C20: 8 | D20: 35 | E20: 25 | F20: 0.35 | G20: 1 | H20: 0.014 | I20: 1.18 | J20: =I20-F20*(1)^0.5 -> 0.83 | K20: =NORMSDIST(I20) -> 0.88099989 | L20: =NORMSDIST(J20) -> 0.79673061 | M20: 11.195 | N20: =IF(B20="Long", 1, -1) * D20 * SQRT(G20) * NORMDIST(I20, 0, 1, FALSE) -> 6.9602092 | O20: =D20 * K20 -> 30.834996
A23: Delta across Positions | H23: Delta across Names
A24: Instrument | B24: Name | C24: Bucket Number | D24: Delta Risk Weight | E24: Delta Cash | F24: WTD Delta Sensitivity | H24: Instrument | I24: Name | J24: Bucket Number | K24: Delta Risk Weight | L24: WTD Delta Sensitivity
A25: Equity A | B25: Eq A | C25: 6 | D25: 0.35 | E25: =O17 -> 40 | F25: =E25*D25 -> 14 | H25: Equity A | I25: Eq A | J25: 6 | K25: 0.35 | L25: =F25+F26 -> 22.005427
A26: European Call on A | B26: Eq A | C26: 6 | D26: 0.35 | E26: =O18 -> 22.872648 | F26: =E26*D26 -> 8.005427 | H26: European Call on B | I26: Eq B | J26: 6 | K26: 0.35 | L26: =F27 -> -3.991791
A27: European Call on B | B27: Eq B | C27: 6 | D27: 0.35 | E27: =O19 -> -11.405117 | F27: =E27*D27 -> -3.991791 | H27: European Call on C | I27: Eq C | J27: 8 | K27: 0.5 | L27: =F28 -> 15.417498
A28: European Call on C | B28: Eq C | C28: 8 | D28: 0.5 | E28: =O20 -> 30.834996 | F28: =E28*D28 -> 15.417498
A31: Intrabucket Correlations
A32: Bucket | B32: Correlation (Rho)
A33: 1-4 | B33: 0.15
A34: 5-8 | B34: 0.25
A35: 9 | B35: 0.075
A36: 10 | B36: 0.125
C39: =L25 -> 22.005427 | D39: =L26 -> -3.991791 | H39: =L25 -> 22.005427 | I39: =L26 -> -3.991791 | M39: =L25 -> 22.005427 | N39: =L26 -> -3.991791
B40: Correlations between EQ A and EQ B (Bucket 6) - Base | G40: Correlations between EQ A and EQ B (Bucket 6) - High | L40: Correlations between EQ A and EQ B (Bucket 6) - Low
C41: Equity A | D41: Equity B | H41: Equity A | I41: Equity B | M41: Equity A | N41: Equity B
A42: =C39 -> 22.005427 | B42: Equity A | C42: 1 | D42: 0.25 | F42: =H39 -> 22.005427 | G42: Equity A | H42: 1 | I42: 0.31 | K42: =M39 -> 22.005427 | L42: Equity A | M42: 1 | N42: 0.19
A43: =D39 -> -3.991791 | B43: Equity B | C43: 0.25 | D43: 1 | F43: =I39 -> -3.991791 | G43: Equity B | H43: 0.31 | I43: 1 | K43: =N39 -> -3.991791 | L43: Equity B | M43: 0.19 | N43: 1
B46: Intrabucket Charges - Base | G46: Intrabucket Charges - High | L46: Intrabucket Charges - High
B47: Bucket 6 | C47: =SQRT(MMULT(C39:D39,MMULT(C42:D43,A42:A43))) -> 21.360072 | G47: Bucket 6 | H47: =SQRT(MMULT(H39:I39,MMULT(H42:I43,F42:F43))) -> 21.111886 | L47: Bucket 6 | M47: =SQRT(MMULT(M39:N39,MMULT(M42:N43,K42:K43))) -> 21.605407
B48: Bucket 8 | C48: =L27 -> 15.417498 | G48: Bucket 8 | H48: =L27 -> 15.417498 | L48: Bucket 8 | M48: =L27 -> 15.417498
B51: Intrabucket Capital Charges
C52: Bucket 6 | D52: Bucket 8
...

Sheet GIRR
A1: GIRR based capital charge
A3: 1. GIRR Delta (EUR is the reporting currency)
A5: Exposure Currency Sensitivities (Sk) | C5: 0.25 | D5: 0.5 | E5: 1 | F5: 2 | G5: 3 | H5: 5 | I5: 10 | J5: 15 | K5: 20 | L5: 30 | S5: Intrabucket Correlation between vertices - Different Curves, Different Vertices (Base) | AR5: Intrabucket Correlation between vertices - Same Curve, Different Vertex (High - 1.25X) | BQ5: Intrabucket Correlation between vertices - Same Curve, Different Vertex (Low - 0.75X) | DB5: =C5 -> 0.25 | DC5: =D5 -> 0.5 | DD5: =E5 -> 1 | DE5: =F5 -> 2 | DF5: =G5 -> 3 | DG5: =H5 -> 5 | DH5: =I5 -> 10 | DI5: =J5 -> 15 | ... DK5: =L5 -> 30
A6: EUR | B6: Curve 1 | C6: 0 | D6: 0 | E6: 4500 | F6: 1200 | G6: 49000 | H6: 310 | I6: 1300 | J6: 1600 | K6: 140 | L6: 0 | M6: =SUM(C6:L6) -> 58050 | P6: FX Rate (EUR per unit CCY) | U6: Curve A | AE6: Curve B | AT6: Curve A | BD6: Curve B | BS6: Curve A | CC6: Curve A | DB6: 0 | DC6: 0 | DD6: 450000 | DE6: 120000 | DF6: 4900000 | DG6: 31000 | DH6: 130000 | DI6: 160000 | DJ6: 14000 | DK6: 0
A7: EUR | B7: Curve 2 | C7: 0 | D7: 0 | E7: 0 | F7: 27000 | G7: 300 | H7: 320 | I7: 360 | J7: 40000 | K7: 0 | L7: 0 | P7: USD | Q7: 0.86 | U7: 0.25 | V7: 0.5 | W7: 1 | X7: 2 | Y7: 3 | Z7: 5 | AA7: 10 | AB7: 15 | AC7: 20 | AD7: 30 | AE7: =U7 -> 0.25 | AF7: =V7 -> 0.5 | AG7: =W7 -> 1 | AH7: =X7 -> 2 | AI7: =Y7 -> 3 | AJ7: =Z7 -> 5 | AK7: =AA7 -> 10 | AL7: =AB7 -> 15 | ... AN7: =AD7 -> 30 | AT7: 0.25 | AU7: 0.5 | AV7: 1 | AW7: 2 | AX7: 3 | AY7: 5 | AZ7: 10 | BA7: 15 | BB7: 20 | BC7: 30 | BD7: =AT7 -> 0.25 | BE7: =AU7 -> 0.5 | BF7: =AV7 -> 1 | BG7: =AW7 -> 2 | BH7: =AX7 -> 3 | BI7: =AY7 -> 5 | BJ7: =AZ7 -> 10 | BK7: =BA7 -> 15 | ... BM7: =BC7 -> 30 | BS7: 0.25 | BT7: 0.5 | BU7: 1 | BV7: 2 | BW7: 3 | BX7: 5 | BY7: 10 | BZ7: 15 | CA7: 20 | CB7: 30 | CC7: =BS7 -> 0.25 | CD7: =BT7 -> 0.5 | CE7: =BU7 -> 1 | CF7: =BV7 -> 2 | CG7: =BW7 -> 3 | CH7: =BX7 -> 5 | CI7: =BY7 -> 10 | CJ7: =BZ7 -> 15 | ... CL7: =CB7 -> 30 | DB7: 0 | DC7: 0 | DD7: 0 | DE7: 2700000 | DF7: 30000 | DG7: 32000 | DH7: 36000 | DI7: 4000000 | DJ7: 0 | DK7: 0
P8: NZD | Q8: 0.64 | S8: Curve A | T8: 0.25 | U8: =MAX(EXP(-3%*(ABS(U$7-$T8))/MIN(U$7,$T8)),40%) -> 1 | V8: =MAX(EXP(-3%*(ABS(V$7-$T8))/MIN(V$7,$T8)),40%) -> 0.97044553 | W8: =MAX(EXP(-3%*(ABS(W$7-$T8))/MIN(W$7,$T8)),40%) -> 0.91393119 | X8: =MAX(EXP(-3%*(ABS(X$7-$T8))/MIN(X$7,$T8)),40%) -> 0.81058425 | Y8: =MAX(EXP(-3%*(ABS(Y$7-$T8))/MIN(Y$7,$T8)),40%) -> 0.71892373 | Z8: =MAX(EXP(-3%*(ABS(Z$7-$T8))/MIN(Z$7,$T8)),40%) -> 0.56552544 | AA8: =MAX(EXP(-3%*(ABS(AA$7-$T8))/MIN(AA$7,$T8)),40%) -> 0.4 | AB8: =MAX(EXP(-3%*(ABS(AB$7-$T8))/MIN(AB$7,$T8)),40%) -> 0.4 | ... AD8: =MAX(EXP(-3%*(ABS(AD$7-$T8))/MIN(AD$7,$T8)),40%) -> 0.4 | AE8: =U18 -> 0.999 | AF8: =V18 -> 0.96947509 | AG8: =W18 -> 0.91301725 | AH8: =X18 -> 0.80977366 | AI8: =Y18 -> 0.71820481 | AJ8: =Z18 -> 0.56495991 | AK8: =AA18 -> 0.3996 | AL8: =AB18 -> 0.3996 | ... AN8: =AD18 -> 0.3996 | AR8: Curve A | AS8: 0.25 | AT8: =MIN(U8*1.25,1) -> 1 | AU8: =MIN(V8*1.25,1) -> 1 | AV8: =MIN(W8*1.25,1) -> 1 | AW8: =MIN(X8*1.25,1) -> 1 | AX8: =MIN(Y8*1.25,1) -> 0.89865467 | AY8: =MIN(Z8*1.25,1) -> 0.7069068 | AZ8: =MIN(AA8*1.25,1) -> 0.5 | BA8: =MIN(AB8*1.25,1) -> 0.5 | ... BC8: =MIN(AD8*1.25,1) -> 0.5 | BD8: =AT18 -> 1 | BE8: =AU18 -> 1 | BF8: =AV18 -> 1 | BG8: =AW18 -> 1 | BH8: =AX18 -> 0.89775601 | BI8: =AY18 -> 0.70619989 | BJ8: =AZ18 -> 0.4995 | BK8: =BA18 -> 0.4995 | ... BM8: =BC18 -> 0.4995 | BQ8: Curve A | BR8: 0.25 | BS8: =IF(BS$7=$BR8,100%,U8*0.75) -> 1 | BT8: =IF(BT$7=$BR8,100%,V8*0.75) -> 0.72783415 | BU8: =IF(BU$7=$BR8,100%,W8*0.75) -> 0.68544839 | BV8: =IF(BV$7=$BR8,100%,X8*0.75) -> 0.60793818 | BW8: =IF(BW$7=$BR8,100%,Y8*0.75) -> 0.5391928 | BX8: =IF(BX$7=$BR8,100%,Z8*0.75) -> 0.42414408 | BY8: =IF(BY$7=$BR8,100%,AA8*0.75) -> 0.3 | BZ8: =IF(BZ$7=$BR8,100%,AB8*0.75) -> 0.3 | ... CB8: =IF(CB$7=$BR8,100%,AD8*0.75) -> 0.3 | CC8: =BS18 -> 0.74925 | CD8: =BT18 -> 0.72710632 | CE8: =BU18 -> 0.68476294 | CF8: =BV18 -> 0.60733025 | CG8: =BW18 -> 0.53865361 | CH8: =BX18 -> 0.42371993 | CI8: =BY18 -> 0.2997 | CJ8: =BZ18 -> 0.2997 | ... CL8: =CB18 -> 0.2997 | DB8: 0 | DC8: 0 | DD8: 0 | DE8: 0 | DF8: 0 | DG8: 0 | DH8: 0 | DI8: 0 | DJ8: 0 | DK8: 0
A9: USD | B9: Curve 3 | C9: 0 | D9: 4200 | E9: 1200 | F9: 1200 | G9: 120 | H9: 21000 | I9: 40000 | J9: 0 | K9: 0 | L9: 0 | T9: 0.5 | U9: =MAX(EXP(-3%*(ABS(U$7-$T9))/MIN(U$7,$T9)),40%) -> 0.97044553 | V9: =MAX(EXP(-3%*(ABS(V$7-$T9))/MIN(V$7,$T9)),40%) -> 1 | W9: =MAX(EXP(-3%*(ABS(W$7-$T9))/MIN(W$7,$T9)),40%) -> 0.97044553 | X9: =MAX(EXP(-3%*(ABS(X$7-$T9))/MIN(X$7,$T9)),40%) -> 0.91393119 | Y9: =MAX(EXP(-3%*(ABS(Y$7-$T9))/MIN(Y$7,$T9)),40%) -> 0.86070798 | Z9: =MAX(EXP(-3%*(ABS(Z$7-$T9))/MIN(Z$7,$T9)),40%) -> 0.76337949 | AA9: =MAX(EXP(-3%*(ABS(AA$7-$T9))/MIN(AA$7,$T9)),40%) -> 0.56552544 | AB9: =MAX(EXP(-3%*(ABS(AB$7-$T9))/MIN(AB$7,$T9)),40%) -> 0.41895155 | ... AD9: =MAX(EXP(-3%*(ABS(AD$7-$T9))/MIN(AD$7,$T9)),40%) -> 0.4 | AE9: =U19 -> 0.96947509 | AF9: =V19 -> 0.999 | AG9: =W19 -> 0.96947509 | AH9: =X19 -> 0.91301725 | AI9: =Y19 -> 0.85984727 | AJ9: =Z19 -> 0.76261611 | AK9: =AA19 -> 0.56495991 | AL9: =AB19 -> 0.4185326 | ... AN9: =AD19 -> 0.3996 | AS9: 0.5 | AT9: =MIN(U9*1.25,1) -> 1 | AU9: =MIN(V9*1.25,1) -> 1 | AV9: =MIN(W9*1.25,1) -> 1 | AW9: =MIN(X9*1.25,1) -> 1 | AX9: =MIN(Y9*1.25,1) -> 1 | AY9: =MIN(Z9*1.25,1) -> 0.95422437 | AZ9: =MIN(AA9*1.25,1) -> 0.7069068 | BA9: =MIN(AB9*1.25,1) -> 0.52368944 | ... BC9: =MIN(AD9*1.25,1) -> 0.5 | BD9: =AT19 -> 1 | BE9: =AU19 -> 1 | BF9: =AV19 -> 1 | BG9: =AW19 -> 1 | BH9: =AX19 -> 1 | BI9: =AY19 -> 0.95327014 | BJ9: =AZ19 -> 0.70619989 | BK9: =BA19 -> 0.52316575 | ... BM9: =BC19 -> 0.4995 | BR9: 0.5 | BS9: =IF(BS$7=$BR9,100%,U9*0.75) -> 0.72783415 | BT9: =IF(BT$7=$BR9,100%,V9*0.75) -> 1 | BU9: =IF(BU$7=$BR9,100%,W9*0.75) -> 0.72783415 | BV9: =IF(BV$7=$BR9,100%,X9*0.75) -> 0.68544839 | BW9: =IF(BW$7=$BR9,100%,Y9*0.75) -> 0.64553098 | BX9: =IF(BX$7=$BR9,100%,Z9*0.75) -> 0.57253462 | BY9: =IF(BY$7=$BR9,100%,AA9*0.75) -> 0.42414408 | BZ9: =IF(BZ$7=$BR9,100%,AB9*0.75) -> 0.31421366 | ... CB9: =IF(CB$7=$BR9,100%,AD9*0.75) -> 0.3 | CC9: =BS19 -> 0.72710632 | CD9: =BT19 -> 0.74925 | CE9: =BU19 -> 0.72710632 | CF9: =BV19 -> 0.68476294 | CG9: =BW19 -> 0.64488545 | CH9: =BX19 -> 0.57196209 | CI9: =BY19 -> 0.42371993 | CJ9: =BZ19 -> 0.31389945 | ... CL9: =CB19 -> 0.2997 | DB9: 0 | DC9: 420000 | DD9: 120000 | DE9: 120000 | DF9: 12000 | DG9: 2100000 | DH9: 4000000 | DI9: 0 | DJ9: 0 | DK9: 0
T10: 1 | U10: =MAX(EXP(-3%*(ABS(U$7-$T10))/MIN(U$7,$T10)),40%) -> 0.91393119 | V10: =MAX(EXP(-3%*(ABS(V$7-$T10))/MIN(V$7,$T10)),40%) -> 0.97044553 | W10: =MAX(EXP(-3%*(ABS(W$7-$T10))/MIN(W$7,$T10)),40%) -> 1 | X10: =MAX(EXP(-3%*(ABS(X$7-$T10))/MIN(X$7,$T10)),40%) -> 0.97044553 | Y10: =MAX(EXP(-3%*(ABS(Y$7-$T10))/MIN(Y$7,$T10)),40%) -> 0.94176453 | Z10: =MAX(EXP(-3%*(ABS(Z$7-$T10))/MIN(Z$7,$T10)),40%) -> 0.88692044 | AA10: =MAX(EXP(-3%*(ABS(AA$7-$T10))/MIN(AA$7,$T10)),40%) -> 0.76337949 | AB10: =MAX(EXP(-3%*(ABS(AB$7-$T10))/MIN(AB$7,$T10)),40%) -> 0.65704682 | ... AD10: =MAX(EXP(-3%*(ABS(AD$7-$T10))/MIN(AD$7,$T10)),40%) -> 0.41895155 | AE10: =U20 -> 0.91301725 | AF10: =V20 -> 0.96947509 | AG10: =W20 -> 0.999 | AH10: =X20 -> 0.96947509 | AI10: =Y20 -> 0.94082277 | AJ10: =Z20 -> 0.88603352 | AK10: =AA20 -> 0.76261611 | AL10: =AB20 -> 0.65638977 | ... AN10: =AD20 -> 0.4185326 | AS10: 1 | AT10: =MIN(U10*1.25,1) -> 1 | AU10: =MIN(V10*1.25,1) -> 1 | AV10: =MIN(W10*1.25,1) -> 1 | AW10: =MIN(X10*1.25,1) -> 1 | AX10: =MIN(Y10*1.25,1) -> 1 | AY10: =MIN(Z10*1.25,1) -> 1 | AZ10: =MIN(AA10*1.25,1) -> 0.95422437 | BA10: =MIN(AB10*1.25,1) -> 0.82130852 | ... BC10: =MIN(AD10*1.25,1) -> 0.52368944 | BD10: =AT20 -> 1 | BE10: =AU20 -> 1 | BF10: =AV20 -> 1 | BG10: =AW20 -> 1 | BH10: =AX20 -> 1 | BI10: =AY20 -> 1 | BJ10: =AZ20 -> 0.95327014 | BK10: =BA20 -> 0.82048722 | ... BM10: =BC20 -> 0.52316575 | BR10: 1 | BS10: =IF(BS$7=$BR10,100%,U10*0.75) -> 0.68544839 | BT10: =IF(BT$7=$BR10,100%,V10*0.75) -> 0.72783415 | BU10: =IF(BU$7=$BR10,100%,W10*0.75) -> 1 | BV10: =IF(BV$7=$BR10,100%,X10*0.75) -> 0.72783415 | BW10: =IF(BW$7=$BR10,100%,Y10*0.75) -> 0.7063234 | BX10: =IF(BX$7=$BR10,100%,Z10*0.75) -> 0.66519033 | BY10: =IF(BY$7=$BR10,100%,AA10*0.75) -> 0.57253462 | BZ10: =IF(BZ$7=$BR10,100%,AB10*0.75) -> 0.49278511 | ... CB10: =IF(CB$7=$BR10,100%,AD10*0.75) -> 0.31421366 | CC10: =BS20 -> 0.68476294 | CD10: =BT20 -> 0.72710632 | CE10: =BU20 -> 0.74925 | CF10: =BV20 -> 0.72710632 | CG10: =BW20 -> 0.70561708 | CH10: =BX20 -> 0.66452514 | CI10: =BY20 -> 0.57196209 | CJ10: =BZ20 -> 0.49229233 | ... CL10: =CB20 -> 0.31389945 | DB10: 0 | DC10: 0 | DD10: 0 | DE10: 0 | DF10: 0 | DG10: 0 | DH10: 0 | DI10: 0 | DJ10: 0 | DK10: 0
A11: NZD | B11: Curve 4 | C11: 0 | D11: 49000 | E11: 12000 | F11: 150 | G11: 140 | H11: 160 | I11: 3200 | J11: 41000 | K11: 21000 | L11: 0 | T11: 2 | U11: =MAX(EXP(-3%*(ABS(U$7-$T11))/MIN(U$7,$T11)),40%) -> 0.81058425 | V11: =MAX(EXP(-3%*(ABS(V$7-$T11))/MIN(V$7,$T11)),40%) -> 0.91393119 | W11: =MAX(EXP(-3%*(ABS(W$7-$T11))/MIN(W$7,$T11)),40%) -> 0.97044553 | X11: =MAX(EXP(-3%*(ABS(X$7-$T11))/MIN(X$7,$T11)),40%) -> 1 | Y11: =MAX(EXP(-3%*(ABS(Y$7-$T11))/MIN(Y$7,$T11)),40%) -> 0.98511194 | Z11: =MAX(EXP(-3%*(ABS(Z$7-$T11))/MIN(Z$7,$T11)),40%) -> 0.95599748 | AA11: =MAX(EXP(-3%*(ABS(AA$7-$T11))/MIN(AA$7,$T11)),40%) -> 0.88692044 | AB11: =MAX(EXP(-3%*(ABS(AB$7-$T11))/MIN(AB$7,$T11)),40%) -> 0.82283466 | ... AD11: =MAX(EXP(-3%*(ABS(AD$7-$T11))/MIN(AD$7,$T11)),40%) -> 0.65704682 | AE11: =U21 -> 0.80977366 | AF11: =V21 -> 0.91301725 | AG11: =W21 -> 0.96947509 | AH11: =X21 -> 0.999 | AI11: =Y21 -> 0.98412683 | AJ11: =Z21 -> 0.95504148 | AK11: =AA21 -> 0.88603352 | AL11: =AB21 -> 0.82201182 | ... AN11: =AD21 -> 0.65638977 | AS11: 2 | AT11: =MIN(U11*1.25,1) -> 1 | AU11: =MIN(V11*1.25,1) -> 1 | AV11: =MIN(W11*1.25,1) -> 1 | AW11: =MIN(X11*1.25,1) -> 1 | AX11: =MIN(Y11*1.25,1) -> 1 | AY11: =MIN(Z11*1.25,1) -> 1 | AZ11: =MIN(AA11*1.25,1) -> 1 | BA11: =MIN(AB11*1.25,1) -> 1 | ... BC11: =MIN(AD11*1.25,1) -> 0.82130852 | BD11: =AT21 -> 1 | BE11: =AU21 -> 1 | BF11: =AV21 -> 1 | BG11: =AW21 -> 1 | BH11: =AX21 -> 1 | BI11: =AY21 -> 1 | BJ11: =AZ21 -> 1 | BK11: =BA21 -> 1 | ... BM11: =BC21 -> 0.82048722 | BR11: 2 | BS11: =IF(BS$7=$BR11,100%,U11*0.75) -> 0.60793818 | BT11: =IF(BT$7=$BR11,100%,V11*0.75) -> 0.68544839 | BU11: =IF(BU$7=$BR11,100%,W11*0.75) -> 0.72783415 | BV11: =IF(BV$7=$BR11,100%,X11*0.75) -> 1 | BW11: =IF(BW$7=$BR11,100%,Y11*0.75) -> 0.73883395 | BX11: =IF(BX$7=$BR11,100%,Z11*0.75) -> 0.71699811 | BY11: =IF(BY$7=$BR11,100%,AA11*0.75) -> 0.66519033 | BZ11: =IF(BZ$7=$BR11,100%,AB11*0.75) -> 0.61712599 | ... CB11: =IF(CB$7=$BR11,100%,AD11*0.75) -> 0.49278511 | CC11: =BS21 -> 0.60733025 | CD11: =BT21 -> 0.68476294 | CE11: =BU21 -> 0.72710632 | CF11: =BV21 -> 0.74925 | CG11: =BW21 -> 0.73809512 | CH11: =BX21 -> 0.71628111 | CI11: =BY21 -> 0.66452514 | CJ11: =BZ21 -> 0.61650887 | ... CL11: =CB21 -> 0.49229233 | DB11: 0 | DC11: 4900000 | DD11: 1200000 | DE11: 15000 | DF11: 14000 | DG11: 16000 | DH11: 320000 | DI11: 4100000 | DJ11: 2100000 | DK11: 0
T12: 3 | U12: =MAX(EXP(-3%*(ABS(U$7-$T12))/MIN(U$7,$T12)),40%) -> 0.71892373 | V12: =MAX(EXP(-3%*(ABS(V$7-$T12))/MIN(V$7,$T12)),40%) -> 0.86070798 | W12: =MAX(EXP(-3%*(ABS(W$7-$T12))/MIN(W$7,$T12)),40%) -> 0.94176453 | X12: =MAX(EXP(-3%*(ABS(X$7-$T12))/MIN(X$7,$T12)),40%) -> 0.98511194 | Y12: =MAX(EXP(-3%*(ABS(Y$7-$T12))/MIN(Y$7,$T12)),40%) -> 1 | Z12: =MAX(EXP(-3%*(ABS(Z$7-$T12))/MIN(Z$7,$T12)),40%) -> 0.98019867 | AA12: =MAX(EXP(-3%*(ABS(AA$7-$T12))/MIN(AA$7,$T12)),40%) -> 0.93239382 | AB12: =MAX(EXP(-3%*(ABS(AB$7-$T12))/MIN(AB$7,$T12)),40%) -> 0.88692044 | ... AD12: =MAX(EXP(-3%*(ABS(AD$7-$T12))/MIN(AD$7,$T12)),40%) -> 0.76337949 | AE12: =U22 -> 0.71820481 | AF12: =V22 -> 0.85984727 | AG12: =W22 -> 0.94082277 | AH12: =X22 -> 0.98412683 | AI12: =Y22 -> 0.999 | AJ12: =Z22 -> 0.97921847 | AK12: =AA22 -> 0.93146143 | AL12: =AB22 -> 0.88603352 | ... AN12: =AD22 -> 0.76261611 | AS12: 3 | AT12: =MIN(U12*1.25,1) -> 0.89865467 | AU12: =MIN(V12*1.25,1) -> 1 | AV12: =MIN(W12*1.25,1) -> 1 | AW12: =MIN(X12*1.25,1) -> 1 | AX12: =MIN(Y12*1.25,1) -> 1 | AY12: =MIN(Z12*1.25,1) -> 1 | AZ12: =MIN(AA12*1.25,1) -> 1 | BA12: =MIN(AB12*1.25,1) -> 1 | ... BC12: =MIN(AD12*1.25,1) -> 0.95422437 | BD12: =AT22 -> 0.89775601 | BE12: =AU22 -> 1 | BF12: =AV22 -> 1 | BG12: =AW22 -> 1 | BH12: =AX22 -> 1 | BI12: =AY22 -> 1 | BJ12: =AZ22 -> 1 | BK12: =BA22 -> 1 | ... BM12: =BC22 -> 0.95327014 | BR12: 3 | BS12: =IF(BS$7=$BR12,100%,U12*0.75) -> 0.5391928 | BT12: =IF(BT$7=$BR12,100%,V12*0.75) -> 0.64553098 | BU12: =IF(BU$7=$BR12,100%,W12*0.75) -> 0.7063234 | BV12: =IF(BV$7=$BR12,100%,X12*0.75) -> 0.73883395 | BW12: =IF(BW$7=$BR12,100%,Y12*0.75) -> 1 | BX12: =IF(BX$7=$BR12,100%,Z12*0.75) -> 0.735149 | BY12: =IF(BY$7=$BR12,100%,AA12*0.75) -> 0.69929536 | BZ12: =IF(BZ$7=$BR12,100%,AB12*0.75) -> 0.66519033 | ... CB12: =IF(CB$7=$BR12,100%,AD12*0.75) -> 0.57253462 | CC12: =BS22 -> 0.53865361 | CD12: =BT22 -> 0.64488545 | CE12: =BU22 -> 0.70561708 | CF12: =BV22 -> 0.73809512 | CG12: =BW22 -> 0.74925 | CH12: =BX22 -> 0.73441386 | CI12: =BY22 -> 0.69859607 | CJ12: =BZ22 -> 0.66452514 | ... CL12: =CB22 -> 0.57196209
T13: 5 | U13: =MAX(EXP(-3%*(ABS(U$7-$T13))/MIN(U$7,$T13)),40%) -> 0.56552544 | V13: =MAX(EXP(-3%*(ABS(V$7-$T13))/MIN(V$7,$T13)),40%) -> 0.76337949 | W13: =MAX(EXP(-3%*(ABS(W$7-$T13))/MIN(W$7,$T13)),40%) -> 0.88692044 | X13: =MAX(EXP(-3%*(ABS(X$7-$T13))/MIN(X$7,$T13)),40%) -> 0.95599748 | Y13: =MAX(EXP(-3%*(ABS(Y$7-$T13))/MIN(Y$7,$T13)),40%) -> 0.98019867 | Z13: =MAX(EXP(-3%*(ABS(Z$7-$T13))/MIN(Z$7,$T13)),40%) -> 1 | AA13: =MAX(EXP(-3%*(ABS(AA$7-$T13))/MIN(AA$7,$T13)),40%) -> 0.97044553 | AB13: =MAX(EXP(-3%*(ABS(AB$7-$T13))/MIN(AB$7,$T13)),40%) -> 0.94176453 | ... AD13: =MAX(EXP(-3%*(ABS(AD$7-$T13))/MIN(AD$7,$T13)),40%) -> 0.86070798 | AE13: =U23 -> 0.56495991 | AF13: =V23 -> 0.76261611 | AG13: =W23 -> 0.88603352 | AH13: =X23 -> 0.95504148 | AI13: =Y23 -> 0.97921847 | AJ13: =Z23 -> 0.999 | AK13: =AA23 -> 0.96947509 | AL13: =AB23 -> 0.94082277 | ... AN13: =AD23 -> 0.85984727 | AS13: 5 | AT13: =MIN(U13*1.25,1) -> 0.7069068 | AU13: =MIN(V13*1.25,1) -> 0.95422437 | AV13: =MIN(W13*1.25,1) -> 1 | AW13: =MIN(X13*1.25,1) -> 1 | AX13: =MIN(Y13*1.25,1) -> 1 | AY13: =MIN(Z13*1.25,1) -> 1 | AZ13: =MIN(AA13*1.25,1) -> 1 | BA13: =MIN(AB13*1.25,1) -> 1 | ... BC13: =MIN(AD13*1.25,1) -> 1 | BD13: =AT23 -> 0.70619989 | BE13: =AU23 -> 0.95327014 | BF13: =AV23 -> 1 | BG13: =AW23 -> 1 | BH13: =AX23 -> 1 | BI13: =AY23 -> 1 | BJ13: =AZ23 -> 1 | BK13: =BA23 -> 1 | ... BM13: =BC23 -> 1 | BR13: 5 | BS13: =IF(BS$7=$BR13,100%,U13*0.75) -> 0.42414408 | BT13: =IF(BT$7=$BR13,100%,V13*0.75) -> 0.57253462 | BU13: =IF(BU$7=$BR13,100%,W13*0.75) -> 0.66519033 | BV13: =IF(BV$7=$BR13,100%,X13*0.75) -> 0.71699811 | BW13: =IF(BW$7=$BR13,100%,Y13*0.75) -> 0.735149 | BX13: =IF(BX$7=$BR13,100%,Z13*0.75) -> 1 | BY13: =IF(BY$7=$BR13,100%,AA13*0.75) -> 0.72783415 | BZ13: =IF(BZ$7=$BR13,100%,AB13*0.75) -> 0.7063234 | ... CB13: =IF(CB$7=$BR13,100%,AD13*0.75) -> 0.64553098 | CC13: =BS23 -> 0.42371993 | CD13: =BT23 -> 0.57196209 | CE13: =BU23 -> 0.66452514 | CF13: =BV23 -> 0.71628111 | CG13: =BW23 -> 0.73441386 | CH13: =BX23 -> 0.74925 | CI13: =BY23 -> 0.72710632 | CJ13: =BZ23 -> 0.70561708 | ... CL13: =CB23 -> 0.64488545
A14: Reporting Currency Sensitivities | C14: 0.25 | D14: 0.5 | E14: 1 | F14: 2 | G14: 3 | H14: 5 | I14: 10 | J14: 15 | K14: 20 | L14: 30 | T14: 10 | U14: =MAX(EXP(-3%*(ABS(U$7-$T14))/MIN(U$7,$T14)),40%) -> 0.4 | V14: =MAX(EXP(-3%*(ABS(V$7-$T14))/MIN(V$7,$T14)),40%) -> 0.56552544 | W14: =MAX(EXP(-3%*(ABS(W$7-$T14))/MIN(W$7,$T14)),40%) -> 0.76337949 | X14: =MAX(EXP(-3%*(ABS(X$7-$T14))/MIN(X$7,$T14)),40%) -> 0.88692044 | Y14: =MAX(EXP(-3%*(ABS(Y$7-$T14))/MIN(Y$7,$T14)),40%) -> 0.93239382 | Z14: =MAX(EXP(-3%*(ABS(Z$7-$T14))/MIN(Z$7,$T14)),40%) -> 0.97044553 | AA14: =MAX(EXP(-3%*(ABS(AA$7-$T14))/MIN(AA$7,$T14)),40%) -> 1 | AB14: =MAX(EXP(-3%*(ABS(AB$7-$T14))/MIN(AB$7,$T14)),40%) -> 0.98511194 | ... AD14: =MAX(EXP(-3%*(ABS(AD$7-$T14))/MIN(AD$7,$T14)),40%) -> 0.94176453 | AE14: =U24 -> 0.3996 | AF14: =V24 -> 0.56495991 | AG14: =W24 -> 0.76261611 | AH14: =X24 -> 0.88603352 | AI14: =Y24 -> 0.93146143 | AJ14: =Z24 -> 0.96947509 | AK14: =AA24 -> 0.999 | AL14: =AB24 -> 0.98412683 | ... AN14: =AD24 -> 0.94082277 | AS14: 10 | AT14: =MIN(U14*1.25,1) -> 0.5 | AU14: =MIN(V14*1.25,1) -> 0.7069068 | AV14: =MIN(W14*1.25,1) -> 0.95422437 | AW14: =MIN(X14*1.25,1) -> 1 | AX14: =MIN(Y14*1.25,1) -> 1 | AY14: =MIN(Z14*1.25,1) -> 1 | AZ14: =MIN(AA14*1.25,1) -> 1 | BA14: =MIN(AB14*1.25,1) -> 1 | ... BC14: =MIN(AD14*1.25,1) -> 1 | BD14: =AT24 -> 0.4995 | BE14: =AU24 -> 0.70619989 | BF14: =AV24 -> 0.95327014 | BG14: =AW24 -> 1 | BH14: =AX24 -> 1 | BI14: =AY24 -> 1 | BJ14: =AZ24 -> 1 | BK14: =BA24 -> 1 | ... BM14: =BC24 -> 1 | BR14: 10 | BS14: =IF(BS$7=$BR14,100%,U14*0.75) -> 0.3 | BT14: =IF(BT$7=$BR14,100%,V14*0.75) -> 0.42414408 | BU14: =IF(BU$7=$BR14,100%,W14*0.75) -> 0.57253462 | BV14: =IF(BV$7=$BR14,100%,X14*0.75) -> 0.66519033 | BW14: =IF(BW$7=$BR14,100%,Y14*0.75) -> 0.69929536 | BX14: =IF(BX$7=$BR14,100%,Z14*0.75) -> 0.72783415 | BY14: =IF(BY$7=$BR14,100%,AA14*0.75) -> 1 | BZ14: =IF(BZ$7=$BR14,100%,AB14*0.75) -> 0.73883395 | ... CB14: =IF(CB$7=$BR14,100%,AD14*0.75) -> 0.7063234 | CC14: =BS24 -> 0.2997 | CD14: =BT24 -> 0.42371993 | CE14: =BU24 -> 0.57196209 | CF14: =BV24 -> 0.66452514 | CG14: =BW24 -> 0.69859607 | CH14: =BX24 -> 0.72710632 | CI14: =BY24 -> 0.74925 | CJ14: =BZ24 -> 0.73809512 | ... CL14: =CB24 -> 0.70561708
A15: EUR | B15: Curve 1 | C15: =C6 -> 0 | D15: =D6 -> 0 | E15: =E6 -> 4500 | F15: =F6 -> 1200 | G15: =G6 -> 49000 | H15: =H6 -> 310 | I15: =I6 -> 1300 | J15: =J6 -> 1600 | ... L15: =L6 -> 0 | T15: 15 | U15: =MAX(EXP(-3%*(ABS(U$7-$T15))/MIN(U$7,$T15)),40%) -> 0.4 | V15: =MAX(EXP(-3%*(ABS(V$7-$T15))/MIN(V$7,$T15)),40%) -> 0.41895155 | W15: =MAX(EXP(-3%*(ABS(W$7-$T15))/MIN(W$7,$T15)),40%) -> 0.65704682 | X15: =MAX(EXP(-3%*(ABS(X$7-$T15))/MIN(X$7,$T15)),40%) -> 0.82283466 | Y15: =MAX(EXP(-3%*(ABS(Y$7-$T15))/MIN(Y$7,$T15)),40%) -> 0.88692044 | Z15: =MAX(EXP(-3%*(ABS(Z$7-$T15))/MIN(Z$7,$T15)),40%) -> 0.94176453 | AA15: =MAX(EXP(-3%*(ABS(AA$7-$T15))/MIN(AA$7,$T15)),40%) -> 0.98511194 | AB15: =MAX(EXP(-3%*(ABS(AB$7-$T15))/MIN(AB$7,$T15)),40%) -> 1 | ... AD15: =MAX(EXP(-3%*(ABS(AD$7-$T15))/MIN(AD$7,$T15)),40%) -> 0.97044553 | AE15: =U25 -> 0.3996 | AF15: =V25 -> 0.4185326 | AG15: =W25 -> 0.65638977 | AH15: =X25 -> 0.82201182 | AI15: =Y25 -> 0.88603352 | AJ15: =Z25 -> 0.94082277 | AK15: =AA25 -> 0.98412683 | AL15: =AB25 -> 0.999 | ... AN15: =AD25 -> 0.96947509 | AS15: 15 | AT15: =MIN(U15*1.25,1) -> 0.5 | AU15: =MIN(V15*1.25,1) -> 0.52368944 | AV15: =MIN(W15*1.25,1) -> 0.82130852 | AW15: =MIN(X15*1.25,1) -> 1 | AX15: =MIN(Y15*1.25,1) -> 1 | AY15: =MIN(Z15*1.25,1) -> 1 | AZ15: =MIN(AA15*1.25,1) -> 1 | BA15: =MIN(AB15*1.25,1) -> 1 | ... BC15: =MIN(AD15*1.25,1) -> 1 | BD15: =AT25 -> 0.4995 | BE15: =AU25 -> 0.52316575 | BF15: =AV25 -> 0.82048722 | BG15: =AW25 -> 1 | BH15: =AX25 -> 1 | BI15: =AY25 -> 1 | BJ15: =AZ25 -> 1 | BK15: =BA25 -> 1 | ... BM15: =BC25 -> 1 | BR15: 15 | BS15: =IF(BS$7=$BR15,100%,U15*0.75) -> 0.3 | BT15: =IF(BT$7=$BR15,100%,V15*0.75) -> 0.31421366 | BU15: =IF(BU$7=$BR15,100%,W15*0.75) -> 0.49278511 | BV15: =IF(BV$7=$BR15,100%,X15*0.75) -> 0.61712599 | BW15: =IF(BW$7=$BR15,100%,Y15*0.75) -> 0.66519033 | BX15: =IF(BX$7=$BR15,100%,Z15*0.75) -> 0.7063234 | BY15: =IF(BY$7=$BR15,100%,AA15*0.75) -> 0.73883395 | BZ15: =IF(BZ$7=$BR15,100%,AB15*0.75) -> 1 | ... CB15: =IF(CB$7=$BR15,100%,AD15*0.75) -> 0.72783415 | CC15: =BS25 -> 0.2997 | CD15: =BT25 -> 0.31389945 | CE15: =BU25 -> 0.49229233 | CF15: =BV25 -> 0.61650887 | CG15: =BW25 -> 0.66452514 | CH15: =BX25 -> 0.70561708 | CI15: =BY25 -> 0.73809512 | CJ15: =BZ25 -> 0.74925 | ... CL15: =CB25 -> 0.72710632
A16: EUR | B16: Curve 2 | C16: =C7 -> 0 | D16: =D7 -> 0 | E16: =E7 -> 0 | F16: =F7 -> 27000 | G16: =G7 -> 300 | H16: =H7 -> 320 | I16: =I7 -> 360 | J16: =J7 -> 40000 | ... L16: =L7 -> 0 | T16: 20 | U16: =MAX(EXP(-3%*(ABS(U$7-$T16))/MIN(U$7,$T16)),40%) -> 0.4 | V16: =MAX(EXP(-3%*(ABS(V$7-$T16))/MIN(V$7,$T16)),40%) -> 0.4 | W16: =MAX(EXP(-3%*(ABS(W$7-$T16))/MIN(W$7,$T16)),40%) -> 0.56552544 | X16: =MAX(EXP(-3%*(ABS(X$7-$T16))/MIN(X$7,$T16)),40%) -> 0.76337949 | Y16: =MAX(EXP(-3%*(ABS(Y$7-$T16))/MIN(Y$7,$T16)),40%) -> 0.84366482 | Z16: =MAX(EXP(-3%*(ABS(Z$7-$T16))/MIN(Z$7,$T16)),40%) -> 0.91393119 | AA16: =MAX(EXP(-3%*(ABS(AA$7-$T16))/MIN(AA$7,$T16)),40%) -> 0.97044553 | AB16: =MAX(EXP(-3%*(ABS(AB$7-$T16))/MIN(AB$7,$T16)),40%) -> 0.99004983 | ... AD16: =MAX(EXP(-3%*(ABS(AD$7-$T16))/MIN(AD$7,$T16)),40%) -> 0.98511194 | AE16: =U26 -> 0.3996 | AF16: =V26 -> 0.3996 | AG16: =W26 -> 0.56495991 | AH16: =X26 -> 0.76261611 | AI16: =Y26 -> 0.84282115 | AJ16: =Z26 -> 0.91301725 | AK16: =AA26 -> 0.96947509 | AL16: =AB26 -> 0.98905978 | ... AN16: =AD26 -> 0.98412683 | AS16: 20 | AT16: =MIN(U16*1.25,1) -> 0.5 | AU16: =MIN(V16*1.25,1) -> 0.5 | AV16: =MIN(W16*1.25,1) -> 0.7069068 | AW16: =MIN(X16*1.25,1) -> 0.95422437 | AX16: =MIN(Y16*1.25,1) -> 1 | AY16: =MIN(Z16*1.25,1) -> 1 | AZ16: =MIN(AA16*1.25,1) -> 1 | BA16: =MIN(AB16*1.25,1) -> 1 | ... BC16: =MIN(AD16*1.25,1) -> 1 | BD16: =AT26 -> 0.4995 | BE16: =AU26 -> 0.4995 | BF16: =AV26 -> 0.70619989 | BG16: =AW26 -> 0.95327014 | BH16: =AX26 -> 1 | BI16: =AY26 -> 1 | BJ16: =AZ26 -> 1 | BK16: =BA26 -> 1 | ... BM16: =BC26 -> 1 | BR16: 20 | BS16: =IF(BS$7=$BR16,100%,U16*0.75) -> 0.3 | BT16: =IF(BT$7=$BR16,100%,V16*0.75) -> 0.3 | BU16: =IF(BU$7=$BR16,100%,W16*0.75) -> 0.42414408 | BV16: =IF(BV$7=$BR16,100%,X16*0.75) -> 0.57253462 | BW16: =IF(BW$7=$BR16,100%,Y16*0.75) -> 0.63274861 | BX16: =IF(BX$7=$BR16,100%,Z16*0.75) -> 0.68544839 | BY16: =IF(BY$7=$BR16,100%,AA16*0.75) -> 0.72783415 | BZ16: =IF(BZ$7=$BR16,100%,AB16*0.75) -> 0.74253738 | ... CB16: =IF(CB$7=$BR16,100%,AD16*0.75) -> 0.73883395 | CC16: =BS26 -> 0.2997 | CD16: =BT26 -> 0.2997 | CE16: =BU26 -> 0.42371993 | CF16: =BV26 -> 0.57196209 | CG16: =BW26 -> 0.63211586 | CH16: =BX26 -> 0.68476294 | CI16: =BY26 -> 0.72710632 | CJ16: =BZ26 -> 0.74179484 | ... CL16: =CB26 -> 0.73809512
T17: 30 | U17: =MAX(EXP(-3%*(ABS(U$7-$T17))/MIN(U$7,$T17)),40%) -> 0.4 | V17: =MAX(EXP(-3%*(ABS(V$7-$T17))/MIN(V$7,$T17)),40%) -> 0.4 | W17: =MAX(EXP(-3%*(ABS(W$7-$T17))/MIN(W$7,$T17)),40%) -> 0.41895155 | X17: =MAX(EXP(-3%*(ABS(X$7-$T17))/MIN(X$7,$T17)),40%) -> 0.65704682 | Y17: =MAX(EXP(-3%*(ABS(Y$7-$T17))/MIN(Y$7,$T17)),40%) -> 0.76337949 | Z17: =MAX(EXP(-3%*(ABS(Z$7-$T17))/MIN(Z$7,$T17)),40%) -> 0.86070798 | AA17: =MAX(EXP(-3%*(ABS(AA$7-$T17))/MIN(AA$7,$T17)),40%) -> 0.94176453 | AB17: =MAX(EXP(-3%*(ABS(AB$7-$T17))/MIN(AB$7,$T17)),40%) -> 0.97044553 | ... AD17: =MAX(EXP(-3%*(ABS(AD$7-$T17))/MIN(AD$7,$T17)),40%) -> 1 | AE17: =U27 -> 0.3996 | AF17: =V27 -> 0.3996 | AG17: =W27 -> 0.4185326 | AH17: =X27 -> 0.65638977 | AI17: =Y27 -> 0.76261611 | AJ17: =Z27 -> 0.85984727 | AK17: =AA27 -> 0.94082277 | AL17: =AB27 -> 0.96947509 | ... AN17: =AD27 -> 0.999 | AS17: 30 | AT17: =MIN(U17*1.25,1) -> 0.5 | AU17: =MIN(V17*1.25,1) -> 0.5 | AV17: =MIN(W17*1.25,1) -> 0.52368944 | AW17: =MIN(X17*1.25,1) -> 0.82130852 | AX17: =MIN(Y17*1.25,1) -> 0.95422437 | AY17: =MIN(Z17*1.25,1) -> 1 | AZ17: =MIN(AA17*1.25,1) -> 1 | BA17: =MIN(AB17*1.25,1) -> 1 | ... BC17: =MIN(AD17*1.25,1) -> 1 | BD17: =AT27 -> 0.4995 | BE17: =AU27 -> 0.4995 | BF17: =AV27 -> 0.52316575 | BG17: =AW27 -> 0.82048722 | BH17: =AX27 -> 0.95327014 | BI17: =AY27 -> 1 | BJ17: =AZ27 -> 1 | BK17: =BA27 -> 1 | ... BM17: =BC27 -> 1 | BR17: 30 | BS17: =IF(BS$7=$BR17,100%,U17*0.75) -> 0.3 | BT17: =IF(BT$7=$BR17,100%,V17*0.75) -> 0.3 | BU17: =IF(BU$7=$BR17,100%,W17*0.75) -> 0.31421366 | BV17: =IF(BV$7=$BR17,100%,X17*0.75) -> 0.49278511 | BW17: =IF(BW$7=$BR17,100%,Y17*0.75) -> 0.57253462 | BX17: =IF(BX$7=$BR17,100%,Z17*0.75) -> 0.64553098 | BY17: =IF(BY$7=$BR17,100%,AA17*0.75) -> 0.7063234 | BZ17: =IF(BZ$7=$BR17,100%,AB17*0.75) -> 0.72783415 | ... CB17: =IF(CB$7=$BR17,100%,AD17*0.75) -> 1 | CC17: =BS27 -> 0.2997 | CD17: =BT27 -> 0.2997 | CE17: =BU27 -> 0.31389945 | CF17: =BV27 -> 0.49229233 | CG17: =BW27 -> 0.57196209 | CH17: =BX27 -> 0.64488545 | CI17: =BY27 -> 0.70561708 | CJ17: =BZ27 -> 0.72710632 | ... CL17: =CB27 -> 0.74925
A18: USD | B18: Curve 3 | C18: =C9*$Q$7 -> 0 | D18: =D9*$Q$7 -> 3612 | E18: =E9*$Q$7 -> 1032 | F18: =F9*$Q$7 -> 1032 | G18: =G9*$Q$7 -> 103.2 | H18: =H9*$Q$7 -> 18060 | I18: =I9*$Q$7 -> 34400 | J18: =J9*$Q$7 -> 0 | ... L18: =L9*$Q$7 -> 0 | S18: Curve B | T18: 0.25 | U18: =U8*99.9% -> 0.999 | V18: =V8*99.9% -> 0.96947509 | W18: =W8*99.9% -> 0.91301725 | X18: =X8*99.9% -> 0.80977366 | Y18: =Y8*99.9% -> 0.71820481 | Z18: =Z8*99.9% -> 0.56495991 | AA18: =AA8*99.9% -> 0.3996 | AB18: =AB8*99.9% -> 0.3996 | ... AD18: =AD8*99.9% -> 0.3996 | AE18: =U8 -> 1 | AF18: =V8 -> 0.97044553 | AG18: =W8 -> 0.91393119 | AH18: =X8 -> 0.81058425 | AI18: =Y8 -> 0.71892373 | AJ18: =Z8 -> 0.56552544 | AK18: =AA8 -> 0.4 | AL18: =AB8 -> 0.4 | ... AN18: =AD8 -> 0.4 | AR18: Curve B | AS18: 0.25 | AT18: =MIN(U18*1.25,1) -> 1 | AU18: =MIN(V18*1.25,1) -> 1 | AV18: =MIN(W18*1.25,1) -> 1 | AW18: =MIN(X18*1.25,1) -> 1 | AX18: =MIN(Y18*1.25,1) -> 0.89775601 | AY18: =MIN(Z18*1.25,1) -> 0.70619989 | AZ18: =MIN(AA18*1.25,1) -> 0.4995 | BA18: =MIN(AB18*1.25,1) -> 0.4995 | ... BC18: =MIN(AD18*1.25,1) -> 0.4995 | BD18: =AT8 -> 1 | BE18: =AU8 -> 1 | BF18: =AV8 -> 1 | BG18: =AW8 -> 1 | BH18: =AX8 -> 0.89865467 | BI18: =AY8 -> 0.7069068 | BJ18: =AZ8 -> 0.5 | BK18: =BA8 -> 0.5 | ... BM18: =BC8 -> 0.5 | BQ18: Curve B | BR18: 0.25 | BS18: =0.75*U18 -> 0.74925 | BT18: =0.75*V18 -> 0.72710632 | BU18: =0.75*W18 -> 0.68476294 | BV18: =0.75*X18 -> 0.60733025 | BW18: =0.75*Y18 -> 0.53865361 | BX18: =0.75*Z18 -> 0.42371993 | BY18: =0.75*AA18 -> 0.2997 | BZ18: =0.75*AB18 -> 0.2997 | ... CB18: =0.75*AD18 -> 0.2997 | CC18: =BS8 -> 1 | CD18: =BT8 -> 0.72783415 | CE18: =BU8 -> 0.68544839 | CF18: =BV8 -> 0.60793818 | CG18: =BW8 -> 0.5391928 | CH18: =BX8 -> 0.42414408 | CI18: =BY8 -> 0.3 | CJ18: =BZ8 -> 0.3 | ... CL18: =CB8 -> 0.3
T19: 0.5 | U19: =U9*99.9% -> 0.96947509 | V19: =V9*99.9% -> 0.999 | W19: =W9*99.9% -> 0.96947509 | X19: =X9*99.9% -> 0.91301725 | Y19: =Y9*99.9% -> 0.85984727 | Z19: =Z9*99.9% -> 0.76261611 | AA19: =AA9*99.9% -> 0.56495991 | AB19: =AB9*99.9% -> 0.4185326 | ... AD19: =AD9*99.9% -> 0.3996 | AE19: =U9 -> 0.97044553 | AF19: =V9 -> 1 | AG19: =W9 -> 0.97044553 | AH19: =X9 -> 0.91393119 | AI19: =Y9 -> 0.86070798 | AJ19: =Z9 -> 0.76337949 | AK19: =AA9 -> 0.56552544 | AL19: =AB9 -> 0.41895155 | ... AN19: =AD9 -> 0.4 | AS19: 0.5 | AT19: =MIN(U19*1.25,1) -> 1 | AU19: =MIN(V19*1.25,1) -> 1 | AV19: =MIN(W19*1.25,1) -> 1 | AW19: =MIN(X19*1.25,1) -> 1 | AX19: =MIN(Y19*1.25,1) -> 1 | AY19: =MIN(Z19*1.25,1) -> 0.95327014 | AZ19: =MIN(AA19*1.25,1) -> 0.70619989 | BA19: =MIN(AB19*1.25,1) -> 0.52316575 | ... BC19: =MIN(AD19*1.25,1) -> 0.4995 | BD19: =AT9 -> 1 | BE19: =AU9 -> 1 | BF19: =AV9 -> 1 | BG19: =AW9 -> 1 | BH19: =AX9 -> 1 | BI19: =AY9 -> 0.95422437 | BJ19: =AZ9 -> 0.7069068 | BK19: =BA9 -> 0.52368944 | ... BM19: =BC9 -> 0.5 | BR19: 0.5 | BS19: =0.75*U19 -> 0.72710632 | BT19: =0.75*V19 -> 0.74925 | BU19: =0.75*W19 -> 0.72710632 | BV19: =0.75*X19 -> 0.68476294 | BW19: =0.75*Y19 -> 0.64488545 | BX19: =0.75*Z19 -> 0.57196209 | BY19: =0.75*AA19 -> 0.42371993 | BZ19: =0.75*AB19 -> 0.31389945 | ... CB19: =0.75*AD19 -> 0.2997 | CC19: =BS9 -> 0.72783415 | CD19: =BT9 -> 1 | CE19: =BU9 -> 0.72783415 | CF19: =BV9 -> 0.68544839 | CG19: =BW9 -> 0.64553098 | CH19: =BX9 -> 0.57253462 | CI19: =BY9 -> 0.42414408 | CJ19: =BZ9 -> 0.31421366 | ... CL19: =CB9 -> 0.3
A20: NZD | B20: Curve 4 | C20: =C11*$Q$8 -> 0 | D20: =D11*$Q$8 -> 31360 | E20: =E11*$Q$8 -> 7680 | F20: =F11*$Q$8 -> 96 | G20: =G11*$Q$8 -> 89.6 | H20: =H11*$Q$8 -> 102.4 | I20: =I11*$Q$8 -> 2048 | J20: =J11*$Q$8 -> 26240 | ... L20: =L11*$Q$8 -> 0 | T20: 1 | U20: =U10*99.9% -> 0.91301725 | V20: =V10*99.9% -> 0.96947509 | W20: =W10*99.9% -> 0.999 | X20: =X10*99.9% -> 0.96947509 | Y20: =Y10*99.9% -> 0.94082277 | Z20: =Z10*99.9% -> 0.88603352 | AA20: =AA10*99.9% -> 0.76261611 | AB20: =AB10*99.9% -> 0.65638977 | ... AD20: =AD10*99.9% -> 0.4185326 | AE20: =U10 -> 0.91393119 | AF20: =V10 -> 0.97044553 | AG20: =W10 -> 1 | AH20: =X10 -> 0.97044553 | AI20: =Y10 -> 0.94176453 | AJ20: =Z10 -> 0.88692044 | AK20: =AA10 -> 0.76337949 | AL20: =AB10 -> 0.65704682 | ... AN20: =AD10 -> 0.41895155 | AS20: 1 | AT20: =MIN(U20*1.25,1) -> 1 | AU20: =MIN(V20*1.25,1) -> 1 | AV20: =MIN(W20*1.25,1) -> 1 | AW20: =MIN(X20*1.25,1) -> 1 | AX20: =MIN(Y20*1.25,1) -> 1 | AY20: =MIN(Z20*1.25,1) -> 1 | AZ20: =MIN(AA20*1.25,1) -> 0.95327014 | BA20: =MIN(AB20*1.25,1) -> 0.82048722 | ... BC20: =MIN(AD20*1.25,1) -> 0.52316575 | BD20: =AT10 -> 1 | BE20: =AU10 -> 1 | BF20: =AV10 -> 1 | BG20: =AW10 -> 1 | BH20: =AX10 -> 1 | BI20: =AY10 -> 1 | BJ20: =AZ10 -> 0.95422437 | BK20: =BA10 -> 0.82130852 | ... BM20: =BC10 -> 0.52368944 | BR20: 1 | BS20: =0.75*U20 -> 0.68476294 | BT20: =0.75*V20 -> 0.72710632 | BU20: =0.75*W20 -> 0.74925 | BV20: =0.75*X20 -> 0.72710632 | BW20: =0.75*Y20 -> 0.70561708 | BX20: =0.75*Z20 -> 0.66452514 | BY20: =0.75*AA20 -> 0.57196209 | BZ20: =0.75*AB20 -> 0.49229233 | ... CB20: =0.75*AD20 -> 0.31389945 | CC20: =BS10 -> 0.68544839 | CD20: =BT10 -> 0.72783415 | CE20: =BU10 -> 1 | CF20: =BV10 -> 0.72783415 | CG20: =BW10 -> 0.7063234 | CH20: =BX10 -> 0.66519033 | CI20: =BY10 -> 0.57253462 | CJ20: =BZ10 -> 0.49278511 | ... CL20: =CB10 -> 0.31421366
T21: 2 | U21: =U11*99.9% -> 0.80977366 | V21: =V11*99.9% -> 0.91301725 | W21: =W11*99.9% -> 0.96947509 | X21: =X11*99.9% -> 0.999 | Y21: =Y11*99.9% -> 0.98412683 | Z21: =Z11*99.9% -> 0.95504148 | AA21: =AA11*99.9% -> 0.88603352 | AB21: =AB11*99.9% -> 0.82201182 | ... AD21: =AD11*99.9% -> 0.65638977 | AE21: =U11 -> 0.81058425 | AF21: =V11 -> 0.91393119 | AG21: =W11 -> 0.97044553 | AH21: =X11 -> 1 | AI21: =Y11 -> 0.98511194 | AJ21: =Z11 -> 0.95599748 | AK21: =AA11 -> 0.88692044 | AL21: =AB11 -> 0.82283466 | ... AN21: =AD11 -> 0.65704682 | AS21: 2 | AT21: =MIN(U21*1.25,1) -> 1 | AU21: =MIN(V21*1.25,1) -> 1 | AV21: =MIN(W21*1.25,1) -> 1 | AW21: =MIN(X21*1.25,1) -> 1 | AX21: =MIN(Y21*1.25,1) -> 1 | AY21: =MIN(Z21*1.25,1) -> 1 | AZ21: =MIN(AA21*1.25,1) -> 1 | BA21: =MIN(AB21*1.25,1) -> 1 | ... BC21: =MIN(AD21*1.25,1) -> 0.82048722 | BD21: =AT11 -> 1 | BE21: =AU11 -> 1 | BF21: =AV11 -> 1 | BG21: =AW11 -> 1 | BH21: =AX11 -> 1 | BI21: =AY11 -> 1 | BJ21: =AZ11 -> 1 | BK21: =BA11 -> 1 | ... BM21: =BC11 -> 0.82130852 | BR21: 2 | BS21: =0.75*U21 -> 0.60733025 | BT21: =0.75*V21 -> 0.68476294 | BU21: =0.75*W21 -> 0.72710632 | BV21: =0.75*X21 -> 0.74925 | BW21: =0.75*Y21 -> 0.73809512 | BX21: =0.75*Z21 -> 0.71628111 | BY21: =0.75*AA21 -> 0.66452514 | BZ21: =0.75*AB21 -> 0.61650887 | ... CB21: =0.75*AD21 -> 0.49229233 | CC21: =BS11 -> 0.60793818 | CD21: =BT11 -> 0.68544839 | CE21: =BU11 -> 0.72783415 | CF21: =BV11 -> 1 | CG21: =BW11 -> 0.73883395 | CH21: =BX11 -> 0.71699811 | CI21: =BY11 -> 0.66519033 | CJ21: =BZ11 -> 0.61712599 | ... CL21: =CB11 -> 0.49278511
T22: 3 | U22: =U12*99.9% -> 0.71820481 | V22: =V12*99.9% -> 0.85984727 | W22: =W12*99.9% -> 0.94082277 | X22: =X12*99.9% -> 0.98412683 | Y22: =Y12*99.9% -> 0.999 | Z22: =Z12*99.9% -> 0.97921847 | AA22: =AA12*99.9% -> 0.93146143 | AB22: =AB12*99.9% -> 0.88603352 | ... AD22: =AD12*99.9% -> 0.76261611 | AE22: =U12 -> 0.71892373 | AF22: =V12 -> 0.86070798 | AG22: =W12 -> 0.94176453 | AH22: =X12 -> 0.98511194 | AI22: =Y12 -> 1 | AJ22: =Z12 -> 0.98019867 | AK22: =AA12 -> 0.93239382 | AL22: =AB12 -> 0.88692044 | ... AN22: =AD12 -> 0.76337949 | AS22: 3 | AT22: =MIN(U22*1.25,1) -> 0.89775601 | AU22: =MIN(V22*1.25,1) -> 1 | AV22: =MIN(W22*1.25,1) -> 1 | AW22: =MIN(X22*1.25,1) -> 1 | AX22: =MIN(Y22*1.25,1) -> 1 | AY22: =MIN(Z22*1.25,1) -> 1 | AZ22: =MIN(AA22*1.25,1) -> 1 | BA22: =MIN(AB22*1.25,1) -> 1 | ... BC22: =MIN(AD22*1.25,1) -> 0.95327014 | BD22: =AT12 -> 0.89865467 | BE22: =AU12 -> 1 | BF22: =AV12 -> 1 | BG22: =AW12 -> 1 | BH22: =AX12 -> 1 | BI22: =AY12 -> 1 | BJ22: =AZ12 -> 1 | BK22: =BA12 -> 1 | ... BM22: =BC12 -> 0.95422437 | BR22: 3 | BS22: =0.75*U22 -> 0.53865361 | BT22: =0.75*V22 -> 0.64488545 | BU22: =0.75*W22 -> 0.70561708 | BV22: =0.75*X22 -> 0.73809512 | BW22: =0.75*Y22 -> 0.74925 | BX22: =0.75*Z22 -> 0.73441386 | BY22: =0.75*AA22 -> 0.69859607 | BZ22: =0.75*AB22 -> 0.66452514 | ... CB22: =0.75*AD22 -> 0.57196209 | CC22: =BS12 -> 0.5391928 | CD22: =BT12 -> 0.64553098 | CE22: =BU12 -> 0.7063234 | CF22: =BV12 -> 0.73883395 | CG22: =BW12 -> 1 | CH22: =BX12 -> 0.735149 | CI22: =BY12 -> 0.69929536 | CJ22: =BZ12 -> 0.66519033 | ... CL22: =CB12 -> 0.57253462
T23: 5 | U23: =U13*99.9% -> 0.56495991 | V23: =V13*99.9% -> 0.76261611 | W23: =W13*99.9% -> 0.88603352 | X23: =X13*99.9% -> 0.95504148 | Y23: =Y13*99.9% -> 0.97921847 | Z23: =Z13*99.9% -> 0.999 | AA23: =AA13*99.9% -> 0.96947509 | AB23: =AB13*99.9% -> 0.94082277 | ... AD23: =AD13*99.9% -> 0.85984727 | AE23: =U13 -> 0.56552544 | AF23: =V13 -> 0.76337949 | AG23: =W13 -> 0.88692044 | AH23: =X13 -> 0.95599748 | AI23: =Y13 -> 0.98019867 | AJ23: =Z13 -> 1 | AK23: =AA13 -> 0.97044553 | AL23: =AB13 -> 0.94176453 | ... AN23: =AD13 -> 0.86070798 | AS23: 5 | AT23: =MIN(U23*1.25,1) -> 0.70619989 | AU23: =MIN(V23*1.25,1) -> 0.95327014 | AV23: =MIN(W23*1.25,1) -> 1 | AW23: =MIN(X23*1.25,1) -> 1 | AX23: =MIN(Y23*1.25,1) -> 1 | AY23: =MIN(Z23*1.25,1) -> 1 | AZ23: =MIN(AA23*1.25,1) -> 1 | BA23: =MIN(AB23*1.25,1) -> 1 | ... BC23: =MIN(AD23*1.25,1) -> 1 | BD23: =AT13 -> 0.7069068 | BE23: =AU13 -> 0.95422437 | BF23: =AV13 -> 1 | BG23: =AW13 -> 1 | BH23: =AX13 -> 1 | BI23: =AY13 -> 1 | BJ23: =AZ13 -> 1 | BK23: =BA13 -> 1 | ... BM23: =BC13 -> 1 | BR23: 5 | BS23: =0.75*U23 -> 0.42371993 | BT23: =0.75*V23 -> 0.57196209 | BU23: =0.75*W23 -> 0.66452514 | BV23: =0.75*X23 -> 0.71628111 | BW23: =0.75*Y23 -> 0.73441386 | BX23: =0.75*Z23 -> 0.74925 | BY23: =0.75*AA23 -> 0.72710632 | BZ23: =0.75*AB23 -> 0.70561708 | ... CB23: =0.75*AD23 -> 0.64488545 | CC23: =BS13 -> 0.42414408 | CD23: =BT13 -> 0.57253462 | CE23: =BU13 -> 0.66519033 | CF23: =BV13 -> 0.71699811 | CG23: =BW13 -> 0.735149 | CH23: =BX13 -> 1 | CI23: =BY13 -> 0.72783415 | CJ23: =BZ13 -> 0.7063234 | ... CL23: =CB13 -> 0.64553098
C24: 0.25 | D24: 0.5 | E24: 1 | F24: 2 | G24: 3 | H24: 5 | I24: 10 | J24: 15 | K24: 20 | L24: 30 | T24: 10 | U24: =U14*99.9% -> 0.3996 | V24: =V14*99.9% -> 0.56495991 | W24: =W14*99.9% -> 0.76261611 | X24: =X14*99.9% -> 0.88603352 | Y24: =Y14*99.9% -> 0.93146143 | Z24: =Z14*99.9% -> 0.96947509 | AA24: =AA14*99.9% -> 0.999 | AB24: =AB14*99.9% -> 0.98412683 | ... AD24: =AD14*99.9% -> 0.94082277 | AE24: =U14 -> 0.4 | AF24: =V14 -> 0.56552544 | AG24: =W14 -> 0.76337949 | AH24: =X14 -> 0.88692044 | AI24: =Y14 -> 0.93239382 | AJ24: =Z14 -> 0.97044553 | AK24: =AA14 -> 1 | AL24: =AB14 -> 0.98511194 | ... AN24: =AD14 -> 0.94176453 | AS24: 10 | AT24: =MIN(U24*1.25,1) -> 0.4995 | AU24: =MIN(V24*1.25,1) -> 0.70619989 | AV24: =MIN(W24*1.25,1) -> 0.95327014 | AW24: =MIN(X24*1.25,1) -> 1 | AX24: =MIN(Y24*1.25,1) -> 1 | AY24: =MIN(Z24*1.25,1) -> 1 | AZ24: =MIN(AA24*1.25,1) -> 1 | BA24: =MIN(AB24*1.25,1) -> 1 | ... BC24: =MIN(AD24*1.25,1) -> 1 | BD24: =AT14 -> 0.5 | BE24: =AU14 -> 0.7069068 | BF24: =AV14 -> 0.95422437 | BG24: =AW14 -> 1 | BH24: =AX14 -> 1 | BI24: =AY14 -> 1 | BJ24: =AZ14 -> 1 | BK24: =BA14 -> 1 | ... BM24: =BC14 -> 1 | BR24: 10 | BS24: =0.75*U24 -> 0.2997 | BT24: =0.75*V24 -> 0.42371993 | BU24: =0.75*W24 -> 0.57196209 | BV24: =0.75*X24 -> 0.66452514 | BW24: =0.75*Y24 -> 0.69859607 | BX24: =0.75*Z24 -> 0.72710632 | BY24: =0.75*AA24 -> 0.74925 | BZ24: =0.75*AB24 -> 0.73809512 | ... CB24: =0.75*AD24 -> 0.70561708 | CC24: =BS14 -> 0.3 | CD24: =BT14 -> 0.42414408 | CE24: =BU14 -> 0.57253462 | CF24: =BV14 -> 0.66519033 | CG24: =BW14 -> 0.69929536 | CH24: =BX14 -> 0.72783415 | CI24: =BY14 -> 1 | CJ24: =BZ14 -> 0.73883395 | ... CL24: =CB14 -> 0.7063234
A25: Non-Selected Currency | C25: 0.024 | D25: 0.024 | E25: 0.0225 | F25: 0.0188 | G25: 0.0173 | H25: 0.015 | I25: 0.015 | J25: 0.015 | K25: 0.015 | L25: 0.015 | T25: 15 | U25: =U15*99.9% -> 0.3996 | V25: =V15*99.9% -> 0.4185326 | W25: =W15*99.9% -> 0.65638977 | X25: =X15*99.9% -> 0.82201182 | Y25: =Y15*99.9% -> 0.88603352 | Z25: =Z15*99.9% -> 0.94082277 | AA25: =AA15*99.9% -> 0.98412683 | AB25: =AB15*99.9% -> 0.999 | ... AD25: =AD15*99.9% -> 0.96947509 | AE25: =U15 -> 0.4 | AF25: =V15 -> 0.41895155 | AG25: =W15 -> 0.65704682 | AH25: =X15 -> 0.82283466 | AI25: =Y15 -> 0.88692044 | AJ25: =Z15 -> 0.94176453 | AK25: =AA15 -> 0.98511194 | AL25: =AB15 -> 1 | ... AN25: =AD15 -> 0.97044553 | AS25: 15 | AT25: =MIN(U25*1.25,1) -> 0.4995 | AU25: =MIN(V25*1.25,1) -> 0.52316575 | AV25: =MIN(W25*1.25,1) -> 0.82048722 | AW25: =MIN(X25*1.25,1) -> 1 | AX25: =MIN(Y25*1.25,1) -> 1 | AY25: =MIN(Z25*1.25,1) -> 1 | AZ25: =MIN(AA25*1.25,1) -> 1 | BA25: =MIN(AB25*1.25,1) -> 1 | ... BC25: =MIN(AD25*1.25,1) -> 1 | BD25: =AT15 -> 0.5 | BE25: =AU15 -> 0.52368944 | BF25: =AV15 -> 0.82130852 | BG25: =AW15 -> 1 | BH25: =AX15 -> 1 | BI25: =AY15 -> 1 | BJ25: =AZ15 -> 1 | BK25: =BA15 -> 1 | ... BM25: =BC15 -> 1 | BR25: 15 | BS25: =0.75*U25 -> 0.2997 | BT25: =0.75*V25 -> 0.31389945 | BU25: =0.75*W25 -> 0.49229233 | BV25: =0.75*X25 -> 0.61650887 | BW25: =0.75*Y25 -> 0.66452514 | BX25: =0.75*Z25 -> 0.70561708 | BY25: =0.75*AA25 -> 0.73809512 | BZ25: =0.75*AB25 -> 0.74925 | ... CB25: =0.75*AD25 -> 0.72710632 | CC25: =BS15 -> 0.3 | CD25: =BT15 -> 0.31421366 | CE25: =BU15 -> 0.49278511 | CF25: =BV15 -> 0.61712599 | CG25: =BW15 -> 0.66519033 | CH25: =BX15 -> 0.7063234 | CI25: =BY15 -> 0.73883395 | CJ25: =BZ15 -> 1 | ... CL25: =CB15 -> 0.72783415
A26: Selected Currency | C26: =C25/SQRT(2) -> 0.016970563 | D26: =D25/SQRT(2) -> 0.016970563 | E26: =E25/SQRT(2) -> 0.015909903 | F26: =F25/SQRT(2) -> 0.013293607 | G26: =G25/SQRT(2) -> 0.012232947 | H26: =H25/SQRT(2) -> 0.010606602 | I26: =I25/SQRT(2) -> 0.010606602 | J26: =J25/SQRT(2) -> 0.010606602 | ... L26: =L25/SQRT(2) -> 0.010606602 | T26: 20 | U26: =U16*99.9% -> 0.3996 | V26: =V16*99.9% -> 0.3996 | W26: =W16*99.9% -> 0.56495991 | X26: =X16*99.9% -> 0.76261611 | Y26: =Y16*99.9% -> 0.84282115 | Z26: =Z16*99.9% -> 0.91301725 | AA26: =AA16*99.9% -> 0.96947509 | AB26: =AB16*99.9% -> 0.98905978 | ... AD26: =AD16*99.9% -> 0.98412683 | AE26: =U16 -> 0.4 | AF26: =V16 -> 0.4 | AG26: =W16 -> 0.56552544 | AH26: =X16 -> 0.76337949 | AI26: =Y16 -> 0.84366482 | AJ26: =Z16 -> 0.91393119 | AK26: =AA16 -> 0.97044553 | AL26: =AB16 -> 0.99004983 | ... AN26: =AD16 -> 0.98511194 | AS26: 20 | AT26: =MIN(U26*1.25,1) -> 0.4995 | AU26: =MIN(V26*1.25,1) -> 0.4995 | AV26: =MIN(W26*1.25,1) -> 0.70619989 | AW26: =MIN(X26*1.25,1) -> 0.95327014 | AX26: =MIN(Y26*1.25,1) -> 1 | AY26: =MIN(Z26*1.25,1) -> 1 | AZ26: =MIN(AA26*1.25,1) -> 1 | BA26: =MIN(AB26*1.25,1) -> 1 | ... BC26: =MIN(AD26*1.25,1) -> 1 | BD26: =AT16 -> 0.5 | BE26: =AU16 -> 0.5 | BF26: =AV16 -> 0.7069068 | BG26: =AW16 -> 0.95422437 | BH26: =AX16 -> 1 | BI26: =AY16 -> 1 | BJ26: =AZ16 -> 1 | BK26: =BA16 -> 1 | ... BM26: =BC16 -> 1 | BR26: 20 | BS26: =0.75*U26 -> 0.2997 | BT26: =0.75*V26 -> 0.2997 | BU26: =0.75*W26 -> 0.42371993 | BV26: =0.75*X26 -> 0.57196209 | BW26: =0.75*Y26 -> 0.63211586 | BX26: =0.75*Z26 -> 0.68476294 | BY26: =0.75*AA26 -> 0.72710632 | BZ26: =0.75*AB26 -> 0.74179484 | ... CB26: =0.75*AD26 -> 0.73809512 | CC26: =BS16 -> 0.3 | CD26: =BT16 -> 0.3 | CE26: =BU16 -> 0.42414408 | CF26: =BV16 -> 0.57253462 | CG26: =BW16 -> 0.63274861 | CH26: =BX16 -> 0.68544839 | CI26: =BY16 -> 0.72783415 | CJ26: =BZ16 -> 0.74253738 | ... CL26: =CB16 -> 0.73883395
T27: 30 | U27: =U17*99.9% -> 0.3996 | V27: =V17*99.9% -> 0.3996 | W27: =W17*99.9% -> 0.4185326 | X27: =X17*99.9% -> 0.65638977 | Y27: =Y17*99.9% -> 0.76261611 | Z27: =Z17*99.9% -> 0.85984727 | AA27: =AA17*99.9% -> 0.94082277 | AB27: =AB17*99.9% -> 0.96947509 | ... AD27: =AD17*99.9% -> 0.999 | AE27: =U17 -> 0.4 | AF27: =V17 -> 0.4 | AG27: =W17 -> 0.41895155 | AH27: =X17 -> 0.65704682 | AI27: =Y17 -> 0.76337949 | AJ27: =Z17 -> 0.86070798 | AK27: =AA17 -> 0.94176453 | AL27: =AB17 -> 0.97044553 | ... AN27: =AD17 -> 1 | AS27: 30 | AT27: =MIN(U27*1.25,1) -> 0.4995 | AU27: =MIN(V27*1.25,1) -> 0.4995 | AV27: =MIN(W27*1.25,1) -> 0.52316575 | AW27: =MIN(X27*1.25,1) -> 0.82048722 | AX27: =MIN(Y27*1.25,1) -> 0.95327014 | AY27: =MIN(Z27*1.25,1) -> 1 | AZ27: =MIN(AA27*1.25,1) -> 1 | BA27: =MIN(AB27*1.25,1) -> 1 | ... BC27: =MIN(AD27*1.25,1) -> 1 | BD27: =AT17 -> 0.5 | BE27: =AU17 -> 0.5 | BF27: =AV17 -> 0.52368944 | BG27: =AW17 -> 0.82130852 | BH27: =AX17 -> 0.95422437 | BI27: =AY17 -> 1 | BJ27: =AZ17 -> 1 | BK27: =BA17 -> 1 | ... BM27: =BC17 -> 1 | BR27: 30 | BS27: =0.75*U27 -> 0.2997 | BT27: =0.75*V27 -> 0.2997 | BU27: =0.75*W27 -> 0.31389945 | BV27: =0.75*X27 -> 0.49229233 | BW27: =0.75*Y27 -> 0.57196209 | BX27: =0.75*Z27 -> 0.64488545 | BY27: =0.75*AA27 -> 0.70561708 | BZ27: =0.75*AB27 -> 0.72710632 | ... CB27: =0.75*AD27 -> 0.74925 | CC27: =BS17 -> 0.3 | CD27: =BT17 -> 0.3 | CE27: =BU17 -> 0.31421366 | CF27: =BV17 -> 0.49278511 | CG27: =BW17 -> 0.57253462 | CH27: =BX17 -> 0.64553098 | CI27: =BY17 -> 0.7063234 | CJ27: =BZ17 -> 0.72783415 | ... CL27: =CB17 -> 1
C28: 0.25 | D28: 0.5 | E28: 1 | F28: 2 | G28: 3 | H28: 5 | I28: 10 | J28: 15 | K28: 20 | L28: 30
A29: EUR | B29: Curve 1 | C29: =C15*C26 -> 0 | D29: =D15*D26 -> 0 | E29: =E15*E26 -> 71.594562 | F29: =F15*F26 -> 15.952329 | G29: =G15*G26 -> 599.41442 | H29: =H15*H26 -> 3.2880465 | I29: =I15*I26 -> 13.788582 | J29: =J15*J26 -> 16.970563 | ... L29: =L15*L26 -> 0
A30: EUR | B30: Curve 2 | C30: =C26*C16 -> 0 | D30: =D26*D16 -> 0 | E30: =E26*E16 -> 0 | F30: =F26*F16 -> 358.9274 | G30: =G26*G16 -> 3.6698842 | H30: =H26*H16 -> 3.3941125 | I30: =I26*I16 -> 3.8183766 | J30: =J26*J16 -> 424.26407 | ... L30: =L26*L16 -> 0
A31: USD | B31: Curve 1 | C31: =C26*C18 -> 0 | D31: =D26*D18 -> 61.297673 | E31: =E26*E18 -> 16.419019 | F31: =F26*F18 -> 13.719003 | G31: =G26*G18 -> 1.2624402 | H31: =H26*H18 -> 191.55523 | I31: =I26*I18 -> 364.8671 | J31: =J26*J18 -> 0 | ... L31: =L26*L18 -> 0
A32: NZD | B32: Curve 1 | C32: =C25*C20 -> 0 | D32: =D25*D20 -> 752.64 | E32: =E25*E20 -> 172.8 | F32: =F25*F20 -> 1.8048 | G32: =G25*G20 -> 1.55008 | H32: =H25*H20 -> 1.536 | I32: =I25*I20 -> 30.72 | J32: =J25*J20 -> 393.6 | ... L32: =L25*L20 -> 0
A36: Intrabucket Aggregation
A38: 1. EUR
B40: Curve 1 | L40: Curve 2
A41: Weighted Sensitivities | B41: =C29 -> 0 | C41: =D29 -> 0 | D41: =E29 -> 71.594562 | E41: =F29 -> 15.952329 | F41: =G29 -> 599.41442 | G41: =H29 -> 3.2880465 | H41: =I29 -> 13.788582 | I41: =J29 -> 16.970563 | ... K41: =L29 -> 0 | L41: =C30 -> 0 | M41: =D30 -> 0 | N41: =E30 -> 0 | O41: =F30 -> 358.9274 | P41: =G30 -> 3.6698842 | Q41: =H30 -> 3.3941125 | R41: =I30 -> 3.8183766 | S41: =J30 -> 424.26407 | ... U41: =L30 -> 0
A42: Tenors | B42: 0.25 | C42: 0.5 | D42: 1 | E42: 2 | F42: 3 | G42: 5 | H42: 10 | I42: 15 | J42: 20 | K42: 30 | L42: 0.25 | M42: 0.5 | N42: 1 | O42: 2 | P42: 3 | Q42: 5 | R42: 10 | S42: 15 | T42: 20 | U42: 30
A44: EUR (at base correlation) | B44: {=SQRT((MMULT(B41:U41, MMULT(U8:AN27,TRANSPOSE(B41:U41)))))} -> 1462.8291
A45: EUR (at high correlation) | B45: {=SQRT((MMULT(B41:U41, MMULT(AT8:BM27,TRANSPOSE(B41:U41)))))} -> 1512.748
A46: EUR (at low correlation) | B46: {=SQRT((MMULT(B41:U41, MMULT(BS8:CL27,TRANSPOSE(B41:U41)))))} -> 1331.6948
A50: 2. USD
B52: Curve 1
...

Sheet Risk_Class_Buckets
A1: S. No. | B1: Risk Class | D1: Risk Bucket | E1: Risk Measure | F1: Risk Factor
A3: 1 | B3: GIRR | E3: Delta
A4: 2 | B4: Credit Spread Risk | C4: Non - Securitization | E4: Vega
A5: 3 | B5: Credit Spread Risk | C5: Securitization - Non correlation trading portfolio | E5: Curvature
A6: 4 | B6: Credit Spread Risk | C6: Securitization - Correlation trading portfolio
A7: 5 | B7: Equity Risk | D7: Mkt Cap Economy (emerging or advanced) Sector - 13 total
A8: 6 | B8: Commodity Risk
A9: 7 | B9: FX Risk

Sheet Delta_Vega_Curvature
B2: Delta | C2: Linear change in value of a financial instrument due to value of a risk factor. Potential loss due to a change in the price of an Equity or Commodity, or a change in the Interest rate, credit spread or FX rate. | D2: Linear | E2: All
B4: Vega | C4: Potential loss resulting from the change in value of a Derivative due to a change in the implied volatility of its underlying. | D4: Linear | E4: Only for Options
B6: Curvature | C6: Additional potential loss beyond Delta Risk due to change in a risk factor for financial instruments with Optionality. In the SA approach, it is based on 2 stress scenarios using upward and downward shock to each regulatory risk factor. | D6: Non Linear | E6: Only for Options

Sheet Notes_Impacts_FRTB
A1: Some Trading Desks may go. | C1: New standardised approach increases risk sensitivity of RWA calculation.
A3: Trading Book - daily MTM. Assets are traded regularly. | C3: Internal models approach using Expected Shortfall (ES) instead of Value-at-Risk (VaR)
A5: Banking book - refers to assets on a Bank's Balance sheet that are supposed to be HTM. Unless there is a reason to believe that the Counter-Party will default on its obligation, thet are held at Historical cost. | C5: Varying liquidity horizons included in the internal models approach. Replaces the static 10 day liquidity horizon currently assumed in the VaR framework.
A7: Capital words means Unexpected capital.
A9: Capital requirement may go up by 40%. Correlation Trading Business has been shut down.
A11: IMA s determined at desk level using the decision framework.
A13: Curvature is not Gamma.
A15: Equity spot price is the biggest risk factor. Equity Delta does not have vertices.
A17: Each instrument with Optionality is subject to Vega Risk and Curvature Risk.
A19: Delta is calculated for all instruments.
A21: No diversification benefit between DELTA and VEGA. They must be added up.
A23: Vega - market input to shock is Volatility. Vega = Implied Volatility * Vega * Risk Weight
A25: Gamma - market input to shock is spot price.
A27: Trading Book is MTM daily under Basel 2 and 3.

Sheet FRTB_Tech_Architecture

Sheet FRTB_Notes
